[2025-08-06 20:00:08] === STARTING PROCESSING ===
[2025-08-06 20:00:08] Target: /opt/coreflow/test_scripts
[2025-08-06 20:00:08] Python: Python 3.12.3
[2025-08-06 20:00:08] Backup: /opt/coreflow/backups/20250806_200008
[2025-08-06 20:00:08] PROCESSING: /opt/coreflow/test_scripts/valid_script.py (Hash: c9720c81)
❌ Invalid: [Errno 2] No such file or directory: '--pre'
[2025-08-06 20:00:08] ⚠️ Pre-validation warnings
[2025-08-06 20:00:08] Attempt 1/3
Traceback (most recent call last):
  File "/opt/coreflow/autonomous/utils/gpt_fixer.py", line 20, in <module>
    from openai import OpenAI
ModuleNotFoundError: No module named 'openai'
[2025-08-06 20:00:08] ❌ Fix attempt 1 failed
[2025-08-06 20:00:08] Attempt 2/3
Traceback (most recent call last):
  File "/opt/coreflow/autonomous/utils/gpt_fixer.py", line 20, in <module>
    from openai import OpenAI
ModuleNotFoundError: No module named 'openai'
[2025-08-06 20:00:09] ❌ Fix attempt 2 failed
[2025-08-06 20:00:09] Attempt 3/3
Traceback (most recent call last):
  File "/opt/coreflow/autonomous/utils/gpt_fixer.py", line 20, in <module>
    from openai import OpenAI
ModuleNotFoundError: No module named 'openai'
[2025-08-06 20:00:09] ❌ Fix attempt 3 failed
[2025-08-06 20:00:09] ♻️ Moved to recovery: /opt/coreflow/autonomous/recovery_queue/valid_script.py.1754503209
[2025-08-06 20:00:09] PROCESSING: /opt/coreflow/test_scripts/invalid_script.py (Hash: 5fc79f27)
❌ Invalid: [Errno 2] No such file or directory: '--pre'
[2025-08-06 20:00:09] ⚠️ Pre-validation warnings
[2025-08-06 20:00:09] Attempt 1/3
Traceback (most recent call last):
  File "/opt/coreflow/autonomous/utils/gpt_fixer.py", line 20, in <module>
    from openai import OpenAI
ModuleNotFoundError: No module named 'openai'
[2025-08-06 20:00:09] ❌ Fix attempt 1 failed
[2025-08-06 20:00:09] Attempt 2/3
Traceback (most recent call last):
  File "/opt/coreflow/autonomous/utils/gpt_fixer.py", line 20, in <module>
    from openai import OpenAI
ModuleNotFoundError: No module named 'openai'
[2025-08-06 20:00:09] ❌ Fix attempt 2 failed
[2025-08-06 20:00:09] Attempt 3/3
Traceback (most recent call last):
  File "/opt/coreflow/autonomous/utils/gpt_fixer.py", line 20, in <module>
    from openai import OpenAI
ModuleNotFoundError: No module named 'openai'
[2025-08-06 20:00:10] ❌ Fix attempt 3 failed
[2025-08-06 20:00:10] ♻️ Moved to recovery: /opt/coreflow/autonomous/recovery_queue/invalid_script.py.1754503210
⚠️ Notification failed: No module named 'infra'
[2025-08-06 20:00:10] === PROCESSING COMPLETE ===
[2025-08-06 20:00:10] Stats saved to /opt/coreflow/logs/autofix/stats_20250806_200008.json
